Workbook

Sheet Masa Kerja
A1: Masa bekerja | B1: Frekuensi | C1: Persentase
A2: < 5 tahun | B2: 23 | C2: 23.2%
A3: 5-10 tahun | B3: 62 | C3: 62.6%
A4: > 15 tahun | B4: 14 | C4: 14.1%
A5: Total | B5: 99 | C5: 1

Sheet Pendidikan Terakhir
A1: No | B1: Pendidikan | C1: Jumlah Responden | D1: Persentase
A2: 1 | B2: SMA/SMK | C2: 44 | D2: 44.4%
A3: 2 | B3: D3 | C3: 38 | D3: 38.4%
A4: 3 | B4: S1/S2 | C4: 17 | D4: 17.2%
A5: Jumlah | C5: 99 | D5: 1

Sheet Jabatan
A1: No | B1: Jabatan | C1: Jumlah Responden | D1: Persentase
A2: 1 | B2: Anggota Pemadam | C2: 43 | D2: =C2/$C$13 -> 0.43434343
A3: 2 | B3: Anggota Tim Penyelamatan | C3: 1 | D3: =C3/$C$13 -> 0.01010101
A4: 3 | B4: Juru Mudi | C4: 29 | D4: =C4/$C$13 -> 0.29292929
A5: 4 | B5: Komandan Peleton | C5: 4 | D5: =C5/$C$13 -> 0.04040404
A6: 5 | B6: Komandan Regu | C6: 7 | D6: =C6/$C$13 -> 0.070707071
A7: 6 | B7: Staff | C7: 8 | D7: =C7/$C$13 -> 0.080808081
A8: 7 | B8: Staff DPKP | C8: 1 | D8: =C8/$C$13 -> 0.01010101
A9: 8 | B9: Staff Pemadaman | C9: 1 | D9: =C9/$C$13 -> 0.01010101
A10: 9 | B10: Staff Pencegahan | C10: 2 | D10: =C10/$C$13 -> 0.02020202
A11: 10 | B11: Staff Sekretariat | C11: 1 | D11: =C11/$C$13 -> 0.01010101
A12: 11 | B12: Tim Rescue | C12: 2 | D12: =C12/$C$13 -> 0.02020202
A13: Jumlah | C13: 99 | D13: =SUM(D2:D12) -> 1

Sheet X1
A1: No | B1: Item | D1: Akumulatif jawaban | I1: Total
D2: STS | E2: TS | F2: KS | G2: S | H2: SS
A3: 1 | B3: X11 | C3: F | D3: 4 | E3: 2 | F3: 12 | G3: 51 | H3: 31 | I3: F | J3: =SUM(D3:H3) -> 100
C4: % | D4: =D3/$J$3 -> 0.04 | E4: =E3/$J$3 -> 0.02 | F4: =F3/$J$3 -> 0.12 | G4: =G3/$J$3 -> 0.51 | H4: =H3/$J$3 -> 0.31 | I4: % | J4: =SUM(D4:H4) -> 1
A5: 2 | B5: X12 | C5: F | D5: 5 | E5: 4 | F5: 17 | G5: 41 | H5: 33 | I5: F | J5: =SUM(D5:H5) -> 100
C6: % | D6: =D5/$J$5 -> 0.05 | E6: =E5/$J$5 -> 0.04 | F6: =F5/$J$5 -> 0.17 | G6: =G5/$J$5 -> 0.41 | H6: =H5/$J$5 -> 0.33 | I6: % | J6: =SUM(D6:H6) -> 1
A7: 3 | B7: X13 | C7: F | D7: 2 | E7: 3 | F7: 17 | G7: 43 | H7: 35 | I7: F | J7: =SUM(D7:H7) -> 100
C8: % | D8: =D7/$J$7 -> 0.02 | E8: =E7/$J$7 -> 0.03 | F8: =F7/$J$7 -> 0.17 | G8: =G7/$J$7 -> 0.43 | H8: =H7/$J$7 -> 0.35 | I8: % | J8: =SUM(D8:H8) -> 1
A9: 4 | B9: X14 | C9: F | D9: 4 | E9: 2 | F9: 19 | G9: 49 | H9: 26 | I9: F | J9: =SUM(D9:H9) -> 100
C10: % | D10: =D9/$J$9 -> 0.04 | E10: =E9/$J$9 -> 0.02 | F10: =F9/$J$9 -> 0.19 | G10: =G9/$J$9 -> 0.49 | H10: =H9/$J$9 -> 0.26 | I10: % | J10: =SUM(D10:H10) -> 1
A11: 5 | B11: X15 | C11: F | D11: 3 | E11: 2 | F11: 16 | G11: 46 | H11: 33 | I11: F | J11: =SUM(D11:H11) -> 100
C12: % | D12: =D11/$J$11 -> 0.03 | E12: =E11/$J$11 -> 0.02 | F12: =F11/$J$11 -> 0.16 | G12: =G11/$J$11 -> 0.46 | H12: =H11/$J$11 -> 0.33 | I12: % | J12: =SUM(D12:H12) -> 1
A13: 6 | B13: X16 | C13: F | D13: 2 | E13: 1 | F13: 14 | G13: 53 | H13: 30 | I13: F | J13: =SUM(D13:H13) -> 100
C14: % | D14: =D13/$J$13 -> 0.02 | E14: =E13/$J$13 -> 0.01 | F14: =F13/$J$13 -> 0.14 | G14: =G13/$J$13 -> 0.53 | H14: =H13/$J$13 -> 0.3 | I14: % | J14: =SUM(D14:H14) -> 1
A15: 7 | B15: X17 | C15: F | D15: 5 | E15: 1 | F15: 11 | G15: 47 | H15: 36 | I15: F | J15: =SUM(D15:H15) -> 100
C16: % | D16: =D15/$J$15 -> 0.05 | E16: =E15/$J$15 -> 0.01 | F16: =F15/$J$15 -> 0.11 | G16: =G15/$J$15 -> 0.47 | H16: =H15/$J$15 -> 0.36 | I16: % | J16: =SUM(D16:H16) -> 1
A18: X11
C19: Frequency | D19: Percent | E19: Valid Percent | F19: Cumulative Percent
A20: Valid | B20: Sangat Tidak Setuju | C20: 4 | D20: 4 | E20: 4 | F20: 4
B21: Tidak Setuju | C21: 2 | D21: 2 | E21: 2 | F21: 6
B22: Kurang Setuju | C22: 12 | D22: 12 | E22: 12 | F22: 18
B23: Setuju | C23: 51 | D23: 51 | E23: 51 | F23: 69
B24: Sangat Setuju | C24: 31 | D24: 31 | E24: 31 | F24: 100
B25: Total | C25: 100 | D25: 100 | E25: 100
A27: X12
C28: Frequency | D28: Percent | E28: Valid Percent | F28: Cumulative Percent
A29: Valid | B29: Sangat Tidak Setuju | C29: 5 | D29: 5 | E29: 5 | F29: 5
B30: Tidak Setuju | C30: 4 | D30: 4 | E30: 4 | F30: 9
B31: Kurang Setuju | C31: 17 | D31: 17 | E31: 17 | F31: 26
B32: Setuju | C32: 41 | D32: 41 | E32: 41 | F32: 67
B33: Sangat Setuju | C33: 33 | D33: 33 | E33: 33 | F33: 100
B34: Total | C34: 100 | D34: 100 | E34: 100
A36: X13
C37: Frequency | D37: Percent | E37: Valid Percent | F37: Cumulative Percent
A38: Valid | B38: Sangat Tidak Setuju | C38: 2 | D38: 2 | E38: 2 | F38: 2
B39: Tidak Setuju | C39: 3 | D39: 3 | E39: 3 | F39: 5
B40: Kurang Setuju | C40: 17 | D40: 17 | E40: 17 | F40: 22
B41: Setuju | C41: 43 | D41: 43 | E41: 43 | F41: 65
B42: Sangat Setuju | C42: 35 | D42: 35 | E42: 35 | F42: 100
B43: Total | C43: 100 | D43: 100 | E43: 100
...

Sheet X2
A1: No | B1: Item | D1: Akumulasi Jawaban | I1: Total
B2: Pernyataan | D2: STS | E2: TS | F2: KS | G2: S | H2: SS
A3: 1 | B3: X21 | C3: F | D3: 2 | E3: 2 | F3: 15 | G3: 50 | H3: 31 | I3: F | J3: =SUM(D3:H3) -> 100
C4: % | D4: =D3/$J$3 -> 0.02 | E4: =E3/$J$3 -> 0.02 | F4: =F3/$J$3 -> 0.15 | G4: =G3/$J$3 -> 0.5 | H4: =H3/$J$3 -> 0.31 | I4: % | J4: =SUM(D4:H4) -> 1
A5: 2 | B5: X22 | C5: F | D5: 2 | E5: 2 | F5: 12 | G5: 43 | H5: 41 | I5: F | J5: =SUM(D5:H5) -> 100
C6: % | D6: =D5/$J$5 -> 0.02 | E6: =E5/$J$5 -> 0.02 | F6: =F5/$J$5 -> 0.12 | G6: =G5/$J$5 -> 0.43 | H6: =H5/$J$5 -> 0.41 | I6: % | J6: =SUM(D6:H6) -> 1
A7: 3 | B7: X23 | C7: F | D7: 3 | E7: 8 | F7: 16 | G7: 49 | H7: 24 | I7: F | J7: =SUM(D7:H7) -> 100
C8: % | D8: =D7/$J$7 -> 0.03 | E8: =E7/$J$7 -> 0.08 | F8: =F7/$J$7 -> 0.16 | G8: =G7/$J$7 -> 0.49 | H8: =H7/$J$7 -> 0.24 | I8: % | J8: =SUM(D8:H8) -> 1
A9: 4 | B9: X24 | C9: F | D9: 1 | E9: 6 | F9: 22 | G9: 39 | H9: 32 | I9: F | J9: =SUM(D9:H9) -> 100
C10: % | D10: =D9/$J$9 -> 0.01 | E10: =E9/$J$9 -> 0.06 | F10: =F9/$J$9 -> 0.22 | G10: =G9/$J$9 -> 0.39 | H10: =H9/$J$9 -> 0.32 | I10: % | J10: =SUM(D10:H10) -> 1
A11: 5 | B11: X25 | C11: F | D11: 1 | E11: 3 | F11: 12 | G11: 49 | H11: 35 | I11: F | J11: =SUM(D11:H11) -> 100
C12: % | D12: =D11/$J$11 -> 0.01 | E12: =E11/$J$11 -> 0.03 | F12: =F11/$J$11 -> 0.12 | G12: =G11/$J$11 -> 0.49 | H12: =H11/$J$11 -> 0.35 | I12: % | J12: =SUM(D12:H12) -> 1
A13: 6 | B13: X26 | C13: F | D13: 2 | E13: 4 | F13: 17 | G13: 47 | H13: 30 | I13: F | J13: =SUM(D13:H13) -> 100
C14: % | D14: =D13/$J$13 -> 0.02 | E14: =E13/$J$13 -> 0.04 | F14: =F13/$J$13 -> 0.17 | G14: =G13/$J$13 -> 0.47 | H14: =H13/$J$13 -> 0.3 | I14: % | J14: =SUM(D14:H14) -> 1
A15: 7 | B15: X27 | C15: F | D15: 1 | E15: 3 | F15: 18 | G15: 46 | H15: 32 | I15: F | J15: =SUM(D15:H15) -> 100
C16: % | D16: =D15/$J$15 -> 0.01 | E16: =E15/$J$15 -> 0.03 | F16: =F15/$J$15 -> 0.18 | G16: =G15/$J$15 -> 0.46 | H16: =H15/$J$15 -> 0.32 | I16: % | J16: =SUM(D16:H16) -> 1
A17: 8 | B17: X28 | C17: F | D17: 2 | E17: 7 | F17: 10 | G17: 45 | H17: 36 | I17: F | J17: =SUM(D17:H17) -> 100
C18: % | D18: =D17/$J$17 -> 0.02 | E18: =E17/$J$17 -> 0.07 | F18: =F17/$J$17 -> 0.1 | G18: =G17/$J$17 -> 0.45 | H18: =H17/$J$17 -> 0.36 | I18: % | J18: =SUM(D18:H18) -> 1
A20: X21
C21: Frequency | D21: Percent | E21: Valid Percent | F21: Cumulative Percent
A22: Valid | B22: Sangat Tidak Setuju | C22: 2 | D22: 2 | E22: 2 | F22: 2
B23: Tidak Setuju | C23: 2 | D23: 2 | E23: 2 | F23: 4
B24: Kurang Setuju | C24: 15 | D24: 15 | E24: 15 | F24: 19
B25: Setuju | C25: 50 | D25: 50 | E25: 50 | F25: 69
B26: Sangat Setuju | C26: 31 | D26: 31 | E26: 31 | F26: 100
B27: Total | C27: 100 | D27: 100 | E27: 100
A29: X22
C30: Frequency | D30: Percent | E30: Valid Percent | F30: Cumulative Percent
A31: Valid | B31: Sangat Tidak Setuju | C31: 2 | D31: 2 | E31: 2 | F31: 2
B32: Tidak Setuju | C32: 2 | D32: 2 | E32: 2 | F32: 4
B33: Kurang Setuju | C33: 12 | D33: 12 | E33: 12 | F33: 16
B34: Setuju | C34: 43 | D34: 43 | E34: 43 | F34: 59
B35: Sangat Setuju | C35: 41 | D35: 41 | E35: 41 | F35: 100
B36: Total | C36: 100 | D36: 100 | E36: 100
A38: X23
C39: Frequency | D39: Percent | E39: Valid Percent | F39: Cumulative Percent
A40: Valid | B40: Sangat Tidak Setuju | C40: 3 | D40: 3 | E40: 3 | F40: 3
B41: Tidak Setuju | C41: 8 | D41: 8 | E41: 8 | F41: 11
B42: Kurang Setuju | C42: 16 | D42: 16 | E42: 16 | F42: 27
B43: Setuju | C43: 49 | D43: 49 | E43: 49 | F43: 76
...

Sheet Y
A1: No | B1: Item Pernyataan | D1: Akumulasi Jawaban | I1: Total
D2: STS | E2: TS | F2: KS | G2: S | H2: SS
A3: 1 | B3: Y1 | C3: F | D3: 2 | E3: 5 | F3: 11 | G3: 39 | H3: 43 | I3: F | J3: =SUM(D3:H3) -> 100
C4: % | D4: =D3/$J$3 -> 0.02 | E4: =E3/$J$3 -> 0.05 | F4: =F3/$J$3 -> 0.11 | G4: =G3/$J$3 -> 0.39 | H4: =H3/$J$3 -> 0.43 | I4: % | J4: =SUM(D4:H4) -> 1
A5: 2 | B5: Y2 | C5: F | D5: 0 | E5: 3 | F5: 7 | G5: 48 | H5: 42 | I5: F | J5: =SUM(D5:H5) -> 100
C6: % | D6: =D5/$J$5 -> 0 | E6: =E5/$J$5 -> 0.03 | F6: =F5/$J$5 -> 0.07 | G6: =G5/$J$5 -> 0.48 | H6: =H5/$J$5 -> 0.42 | I6: % | J6: =SUM(D6:H6) -> 1
A7: 3 | B7: Y3 | C7: F | D7: 1 | E7: 1 | F7: 19 | G7: 54 | H7: 25 | I7: F | J7: =SUM(D7:H7) -> 100
C8: % | D8: =D7/$J$7 -> 0.01 | E8: =E7/$J$7 -> 0.01 | F8: =F7/$J$7 -> 0.19 | G8: =G7/$J$7 -> 0.54 | H8: =H7/$J$7 -> 0.25 | I8: % | J8: =SUM(D8:H8) -> 1
A9: 4 | B9: Y4 | C9: F | D9: 2 | E9: 5 | F9: 12 | G9: 50 | H9: 31 | I9: F | J9: =SUM(D9:H9) -> 100
C10: % | D10: =D9/$J$9 -> 0.02 | E10: =E9/$J$9 -> 0.05 | F10: =F9/$J$9 -> 0.12 | G10: =G9/$J$9 -> 0.5 | H10: =H9/$J$9 -> 0.31 | I10: % | J10: =SUM(D10:H10) -> 1
A11: 5 | B11: Y5 | C11: F | D11: 2 | E11: 4 | F11: 13 | G11: 52 | H11: 29 | I11: F | J11: =SUM(D11:H11) -> 100
C12: % | D12: =D11/$J$11 -> 0.02 | E12: =E11/$J$11 -> 0.04 | F12: =F11/$J$11 -> 0.13 | G12: =G11/$J$11 -> 0.52 | H12: =H11/$J$11 -> 0.29 | I12: % | J12: =SUM(D12:H12) -> 1
A14: Y1
C15: Frequency | D15: Percent | E15: Valid Percent | F15: Cumulative Percent
A16: Valid | B16: Sangat Tidak Setuju | C16: 2 | D16: 2 | E16: 2 | F16: 2
B17: Tidak Setuju | C17: 5 | D17: 5 | E17: 5 | F17: 7
B18: Kurang Setuju | C18: 11 | D18: 11 | E18: 11 | F18: 18
B19: Setuju | C19: 39 | D19: 39 | E19: 39 | F19: 57
B20: Sangat Setuju | C20: 43 | D20: 43 | E20: 43 | F20: 100
B21: Total | C21: 100 | D21: 100 | E21: 100
A23: Y2
C24: Frequency | D24: Percent | E24: Valid Percent | F24: Cumulative Percent
A25: Valid | B25: Tidak Setuju | C25: 3 | D25: 3 | E25: 3 | F25: 3
B26: Kurang Setuju | C26: 7 | D26: 7 | E26: 7 | F26: 10
B27: Setuju | C27: 48 | D27: 48 | E27: 48 | F27: 58
B28: Sangat Setuju | C28: 42 | D28: 42 | E28: 42 | F28: 100
B29: Total | C29: 100 | D29: 100 | E29: 100
A31: Y3
C32: Frequency | D32: Percent | E32: Valid Percent | F32: Cumulative Percent
A33: Valid | B33: Sangat Tidak Setuju | C33: 1 | D33: 1 | E33: 1 | F33: 1
B34: Tidak Setuju | C34: 1 | D34: 1 | E34: 1 | F34: 2
B35: Kurang Setuju | C35: 19 | D35: 19 | E35: 19 | F35: 21
B36: Setuju | C36: 54 | D36: 54 | E36: 54 | F36: 75
B37: Sangat Setuju | C37: 25 | D37: 25 | E37: 25 | F37: 100
B38: Total | C38: 100 | D38: 100 | E38: 100
A40: Y4
C41: Frequency | D41: Percent | E41: Valid Percent | F41: Cumulative Percent
A42: Valid | B42: Sangat Tidak Setuju | C42: 2 | D42: 2 | E42: 2 | F42: 2
B43: Tidak Setuju | C43: 5 | D43: 5 | E43: 5 | F43: 7
B44: Kurang Setuju | C44: 12 | D44: 12 | E44: 12 | F44: 19
...

Sheet Validitas
A1: Variabel | B1: Item | C1: R | D1: Probabilitas | E1: Keterangan
A2: Lingkungan Kerja (X1) | B2: X11 | C2: {=INDEX('Validity Result'!C:C, 2*ROW('Validity Result'!C1)-1)} -> 0,773** | D2: {=INDEX('Validity Result'!C:C, 2*ROW('Validity Result'!C1))} -> 4.7008776e-21 | E2: =IF(D2<0.05,"Valid","Tidak Valid") -> Valid
B3: X12 | C3: {=INDEX('Validity Result'!C:C, 2*ROW('Validity Result'!C2)-1)} -> 0,710** | D3: {=INDEX('Validity Result'!C:C, 2*ROW('Validity Result'!C2))} -> 1.4191867e-16 | E3: =IF(D3<0.05,"Valid","Tidak Valid") -> Valid
B4: X13 | C4: {=INDEX('Validity Result'!C:C, 2*ROW('Validity Result'!C3)-1)} -> 0,647** | D4: {=INDEX('Validity Result'!C:C, 2*ROW('Validity Result'!C3))} -> 3.5940333e-13 | E4: =IF(D4<0.05,"Valid","Tidak Valid") -> Valid
B5: X14 | C5: {=INDEX('Validity Result'!C:C, 2*ROW('Validity Result'!C4)-1)} -> 0,704** | D5: {=INDEX('Validity Result'!C:C, 2*ROW('Validity Result'!C4))} -> 3.0310911e-16 | E5: =IF(D5<0.05,"Valid","Tidak Valid") -> Valid
B6: X15 | C6: {=INDEX('Validity Result'!C:C, 2*ROW('Validity Result'!C5)-1)} -> 0,800** | D6: {=INDEX('Validity Result'!C:C, 2*ROW('Validity Result'!C5))} -> 1.8031787e-23 | E6: =IF(D6<0.05,"Valid","Tidak Valid") -> Valid
B7: X16 | C7: {=INDEX('Validity Result'!C:C, 2*ROW('Validity Result'!C6)-1)} -> 0,758** | D7: {=INDEX('Validity Result'!C:C, 2*ROW('Validity Result'!C6))} -> 6.5687207e-20 | E7: =IF(D7<0.05,"Valid","Tidak Valid") -> Valid
B8: X17 | C8: {=INDEX('Validity Result'!C:C, 2*ROW('Validity Result'!C7)-1)} -> 0,772** | D8: {=INDEX('Validity Result'!C:C, 2*ROW('Validity Result'!C7))} -> 4.9119019e-21 | E8: =IF(D8<0.05,"Valid","Tidak Valid") -> Valid
A9: Disiplin Kerja (X2) | B9: X21 | C9: {=INDEX('Validity Result'!C:C, 2*ROW('Validity Result'!C8)-1)} -> 0,765** | D9: {=INDEX('Validity Result'!C:C, 2*ROW('Validity Result'!C8))} -> 1.8697036e-20 | E9: =IF(D9<0.05,"Valid","Tidak Valid") -> Valid
B10: X22 | C10: {=INDEX('Validity Result'!C:C, 2*ROW('Validity Result'!C9)-1)} -> 0,719** | D10: {=INDEX('Validity Result'!C:C, 2*ROW('Validity Result'!C9))} -> 3.4051902e-17 | E10: =IF(D10<0.05,"Valid","Tidak Valid") -> Valid
B11: X23 | C11: {=INDEX('Validity Result'!C:C, 2*ROW('Validity Result'!C10)-1)} -> 0,599** | D11: {=INDEX('Validity Result'!C:C, 2*ROW('Validity Result'!C10))} -> 4.8093236e-11 | E11: =IF(D11<0.05,"Valid","Tidak Valid") -> Valid
B12: X24 | C12: {=INDEX('Validity Result'!C:C, 2*ROW('Validity Result'!C11)-1)} -> 0,648** | D12: {=INDEX('Validity Result'!C:C, 2*ROW('Validity Result'!C11))} -> 3.0677113e-13 | E12: =IF(D12<0.05,"Valid","Tidak Valid") -> Valid
B13: X25 | C13: {=INDEX('Validity Result'!C:C, 2*ROW('Validity Result'!C12)-1)} -> 0,681** | D13: {=INDEX('Validity Result'!C:C, 2*ROW('Validity Result'!C12))} -> 6.746482e-15 | E13: =IF(D13<0.05,"Valid","Tidak Valid") -> Valid
B14: X26 | C14: {=INDEX('Validity Result'!C:C, 2*ROW('Validity Result'!C13)-1)} -> 0,566** | D14: {=INDEX('Validity Result'!C:C, 2*ROW('Validity Result'!C13))} -> 8.4590417e-10 | E14: =IF(D14<0.05,"Valid","Tidak Valid") -> Valid
B15: X27 | C15: {=INDEX('Validity Result'!C:C, 2*ROW('Validity Result'!C14)-1)} -> 0,567** | D15: {=INDEX('Validity Result'!C:C, 2*ROW('Validity Result'!C14))} -> 7.4892643e-10 | E15: =IF(D15<0.05,"Valid","Tidak Valid") -> Valid
B16: X28 | C16: {=INDEX('Validity Result'!C:C, 2*ROW('Validity Result'!C15)-1)} -> 0,583** | D16: {=INDEX('Validity Result'!C:C, 2*ROW('Validity Result'!C15))} -> 2.0160643e-10 | E16: =IF(D16<0.05,"Valid","Tidak Valid") -> Valid
A17: Kinerja Pegawai (Y) | B17: Y1 | C17: {=INDEX('Validity Result'!C:C, 2*ROW('Validity Result'!C16)-1)} -> 0,722** | D17: {=INDEX('Validity Result'!C:C, 2*ROW('Validity Result'!C16))} -> 2.2973328e-17 | E17: =IF(D17<0.05,"Valid","Tidak Valid") -> Valid
B18: Y2 | C18: {=INDEX('Validity Result'!C:C, 2*ROW('Validity Result'!C17)-1)} -> 0,722** | D18: {=INDEX('Validity Result'!C:C, 2*ROW('Validity Result'!C17))} -> 2.4539873e-17 | E18: =IF(D18<0.05,"Valid","Tidak Valid") -> Valid
B19: Y3 | C19: {=INDEX('Validity Result'!C:C, 2*ROW('Validity Result'!C18)-1)} -> 0,606** | D19: {=INDEX('Validity Result'!C:C, 2*ROW('Validity Result'!C18))} -> 2.445645e-11 | E19: =IF(D19<0.05,"Valid","Tidak Valid") -> Valid
B20: Y4 | C20: {=INDEX('Validity Result'!C:C, 2*ROW('Validity Result'!C19)-1)} -> 0,717** | D20: {=INDEX('Validity Result'!C:C, 2*ROW('Validity Result'!C19))} -> 4.9746069e-17 | E20: =IF(D20<0.05,"Valid","Tidak Valid") -> Valid
B21: Y5 | C21: {=INDEX('Validity Result'!C:C, 2*ROW('Validity Result'!C20)-1)} -> 0,776** | D21: {=INDEX('Validity Result'!C:C, 2*ROW('Validity Result'!C20))} -> 2.3165307e-21 | E21: =IF(D21<0.05,"Valid","Tidak Valid") -> Valid

Sheet Validity Result
A1: X11 | B1: Pearson Correlation | C1: 0,773**
B2: Sig. (2-tailed) | C2: 4.7008776e-21
A3: X12 | B3: Pearson Correlation | C3: 0,710**
B4: Sig. (2-tailed) | C4: 1.4191867e-16
A5: X13 | B5: Pearson Correlation | C5: 0,647**
B6: Sig. (2-tailed) | C6: 3.5940333e-13
A7: X14 | B7: Pearson Correlation | C7: 0,704**
B8: Sig. (2-tailed) | C8: 3.0310911e-16
A9: X15 | B9: Pearson Correlation | C9: 0,800**
B10: Sig. (2-tailed) | C10: 1.8031787e-23
A11: X16 | B11: Pearson Correlation | C11: 0,758**
B12: Sig. (2-tailed) | C12: 6.5687207e-20
A13: X17 | B13: Pearson Correlation | C13: 0,772**
B14: Sig. (2-tailed) | C14: 4.9119019e-21
A15: X21 | B15: Pearson Correlation | C15: 0,765**
B16: Sig. (2-tailed) | C16: 1.8697036e-20
A17: X22 | B17: Pearson Correlation | C17: 0,719**
B18: Sig. (2-tailed) | C18: 3.4051902e-17
A19: X23 | B19: Pearson Correlation | C19: 0,599**
B20: Sig. (2-tailed) | C20: 4.8093236e-11
A21: X24 | B21: Pearson Correlation | C21: 0,648**
B22: Sig. (2-tailed) | C22: 3.0677113e-13
A23: X25 | B23: Pearson Correlation | C23: 0,681**
B24: Sig. (2-tailed) | C24: 6.746482e-15
A25: X26 | B25: Pearson Correlation | C25: 0,566**
B26: Sig. (2-tailed) | C26: 8.4590417e-10
A27: X27 | B27: Pearson Correlation | C27: 0,567**
B28: Sig. (2-tailed) | C28: 7.4892643e-10
A29: X28 | B29: Pearson Correlation | C29: 0,583**
B30: Sig. (2-tailed) | C30: 2.0160643e-10
A31: Y1 | B31: Pearson Correlation | C31: 0,722**
B32: Sig. (2-tailed) | C32: 2.2973328e-17
A33: Y2 | B33: Pearson Correlation | C33: 0,722**
B34: Sig. (2-tailed) | C34: 2.4539873e-17
A35: Y3 | B35: Pearson Correlation | C35: 0,606**
B36: Sig. (2-tailed) | C36: 2.445645e-11
A37: Y4 | B37: Pearson Correlation | C37: 0,717**
B38: Sig. (2-tailed) | C38: 4.9746069e-17
A39: Y5 | B39: Pearson Correlation | C39: 0,776**
B40: Sig. (2-tailed) | C40: 2.3165307e-21

Sheet Reliabilitas
A1: Variabel | B1: Alpha | C1: Keterangan
A2: Lingkungan Kerja (X1) | B2: ='Reliability Result'!B2 -> 0.85838038 | C2: =IF(B2>0.7,"Reliabel","Tidak Reliabel") -> Reliabel
A3: Disiplin Kerja (X2) | B3: ='Reliability Result'!B3 -> 0.79153893 | C3: =IF(B3>0.7,"Reliabel","Tidak Reliabel") -> Reliabel
A4: Kinerja Pegawai (Y) | B4: ='Reliability Result'!B4 -> 0.75070988 | C4: =IF(B4>0.7,"Reliabel","Tidak Reliabel") -> Reliabel

Sheet Reliability Result
B1: Cronbach's Alpha | C1: N of Items
A2: Lingkungan Kerja (X1) | B2: 0.85838038 | C2: 7
A3: Disiplin Kerja (X2) | B3: 0.79153893 | C3: 8
A4: Kinerja Pegawai (Y) | B4: 0.75070988 | C4: 5

Sheet Multikolinieritas
A1: No. | B1: Variabel Bebas | C1: Tolerance | D1: VIF | E1: Keterangan
A2: 1. | B2: Lingkungan Kerja (X1) | C2: ='Multicol Result'!H5 -> 0.44314082 | D2: ='Multicol Result'!I5 -> 2.256619 | E2: =IF(D2<10,"Tidak Multikolinier","Multikolinier") -> Tidak Multikolinier
A3: 2. | B3: Disiplin Kerja (X2) | C3: ='Multicol Result'!H6 -> 0.44314082 | D3: ='Multicol Result'!I6 -> 2.256619 | E3: =IF(D3<10,"Tidak Multikolinier","Multikolinier") -> Tidak Multikolinier

Sheet Multicol Result
A1: Coefficientsa
A2: Model | C2: Unstandardized Coefficients | E2: Standardized Coefficients | F2: t | G2: Sig. | H2: Collinearity Statistics
C3: B | D3: Std. Error | E3: Beta | H3: Tolerance | I3: VIF
A4: 1 | B4: (Constant) | C4: 6.8138266 | D4: 1.6428426 | F4: 4.1475833 | G4: 7.205597e-05
B5: X1 | C5: 0.1963958 | D5: 0.071265713 | E5: 0.31659231 | F5: 2.7558246 | G5: 0.0069937738 | H5: 0.44314082 | I5: 2.256619
B6: X2 | C6: 0.25322465 | D6: 0.075194109 | E6: 0.38687525 | F6: 3.3676129 | G6: 0.0010884281 | H6: 0.44314082 | I6: 2.256619
A7: a. Dependent Variable: Y

Sheet Homoskedastisitas
A1: Variabel bebas | B1: Sig. | C1: Keterangan
A2: Lingkungan Kerja (X1) | B2: ='Homoscedasticity Result'!G5 -> 0.8627531 | C2: =IF(B2>0.05,"Homoskedastisitas","Heteroskedastisitas") -> Homoskedastisitas
A3: Disiplin Kerja (X2) | B3: ='Homoscedasticity Result'!G6 -> 0.41769942 | C3: =IF(B3>0.05,"Homoskedastisitas","Heteroskedastisitas") -> Homoskedastisitas

Sheet Homoscedasticity Result
A1: Coefficientsa
A2: Model | C2: Unstandardized Coefficients | E2: Standardized Coefficients | F2: t | G2: Sig. | H2: Collinearity Statistics
C3: B | D3: Std. Error | E3: Beta | H3: Tolerance | I3: VIF
A4: 1 | B4: (Constant) | C4: -0.020369056 | D4: 1.1442434 | F4: -0.017801332 | G4: 0.98583391
B5: X1 | C5: 0.008603541 | D5: 0.04963672 | E5: 0.026163925 | F5: 0.17333017 | G5: 0.8627531 | H5: 0.44314082 | I5: 2.256619
B6: X2 | C6: 0.042625931 | D6: 0.052372856 | E6: 0.12285599 | F6: 0.81389357 | G6: 0.41769942 | H6: 0.44314082 | I6: 2.256619
A7: a. Dependent Variable: AbsRes
